<?xml version="1.0" ?>
<!-- This URDF was automatically created by SolidWorks to URDF Exporter! Originally created by Stephen Brawner (brawner@gmail.com) 
     Commit Version: 1.6.0-4-g7f85cfe  Build Version: 1.6.7995.38578
     For more information, please see http://wiki.ros.org/sw_urdf_exporter -->
<robot
  name="car" xmlns:xacro="http://ros.org/wiki/xacro">
  <link
    name="base_link">
    <inertial>
      <origin
        xyz="-0.262324820535648 -0.111783715901356 0.104432242145527"
        rpy="0 0 0" />
      <mass
        value="130.703413258806" />
      <inertia
        ixx="9.48205817837113"
        ixy="0.000348135237947743"
        ixz="-0.00171562144848398"
        iyy="10.198183829728"
        iyz="1.39608345056877"
        izz="4.24086781721853" />
    </inertial>
    <visual>
      <origin
        xyz="0 0 0"
        rpy="0 0 0" />
      <geometry>
        <mesh
          filename="package://car/meshes/base_link.dae" />
      </geometry>
      <material
        name="">
        <color
          rgba="0.792156862745098 0.819607843137255 0.933333333333333 1" />
      </material>
    </visual>
    <collision>
      <origin
        xyz="0 0 0"
        rpy="0 0 0" />
      <geometry>
        <mesh
          filename="package://car/meshes/base_link.dae" />
      </geometry>
    </collision>
  </link>
    <!-- # Add this after base link
  <joint name="dummy_joint" type="fixed">
      <origin rpy="0 0 0" xyz="0 0 0" />
      <parent link="dummy_link"/>
      <child link="base_link"/>
  </joint> -->
  <link
    name="lidar">
    <inertial>
      <origin
        xyz="-7.04297731246584E-16 2.77555756156289E-16 0.0381059276546113"
        rpy="0 0 0" />
      <mass
        value="2.47069918222367" />
      <inertia
        ixx="0.00757222005312619"
        ixy="0"
        ixz="5.51268534132472E-17"
        iyy="0.00757222005312619"
        iyz="-1.4627147415681E-18"
        izz="0.0127540906436804" />
    </inertial>
    <visual>
      <origin
        xyz="0 0 0"
        rpy="0 0 0" />
      <geometry>
        <mesh
          filename="package://car/meshes/lidar.dae" />
      </geometry>
      <material
        name="">
        <color
          rgba="0.0980392156862745 0.0980392156862745 0.0980392156862745 1" />
      </material>
    </visual>
    <collision>
      <origin
        xyz="0 0 0"
        rpy="0 0 0" />
      <geometry>
        <mesh
          filename="package://car/meshes/lidar.dae" />
      </geometry>
    </collision>
  </link>
  <joint
    name="lidar_joint"
    type="continuous">
    <origin
      xyz="-0.26235 0.018825 0.12175"
      rpy="0 0 -1.548" />
    <parent
      link="base_link" />
    <child
      link="lidar" />
    <axis
      xyz="0 0 1" />
  </joint>
  <link
    name="left_rear_wheel">
    <inertial>
      <origin
        xyz="0 0 -0.0420011070356851"
        rpy="0 0 0" />
      <mass
        value="2.20373338840704" />
      <inertia
        ixx="0.00679098454718218"
        ixy="-2.16840434497101E-19"
        ixz="3.05543041953963E-19"
        iyy="0.00679098454718218"
        iyz="-2.61427869463836E-19"
        izz="0.0118184008419413" />
    </inertial>
    <visual>
      <origin
        xyz="0 0 0"
        rpy="0 0 0" />
      <geometry>
        <mesh
          filename="package://car/meshes/left_rear_wheel.dae" />
      </geometry>
      <material
        name="">
        <color
          rgba="0.792156862745098 0.819607843137255 0.933333333333333 1" />
      </material>
    </visual>
    <collision>
      <origin
        xyz="0 0 0"
        rpy="0 0 0" />
      <geometry>
        <mesh
          filename="package://car/meshes/left_rear_wheel.dae" />
      </geometry>
    </collision>
  </link>
  <joint
    name="left_rear_wheel_joint"
    type="continuous">
    <origin
      xyz="-0.008348 0.035982 -0.33569"
      rpy="-1.5708 -0.65705 -1.5708" />
    <parent
      link="base_link" />
    <child
      link="left_rear_wheel" />
    <axis
      xyz="0 0 1" />
  </joint>
  <link
    name="right_rear_wheel">
    <inertial>
      <origin
        xyz="2.16493489801906E-15 3.11556336285435E-15 0.034198892964327"
        rpy="0 0 0" />
      <mass
        value="2.20373338840704" />
      <inertia
        ixx="0.00679098454718218"
        ixy="7.75561000518877E-33"
        ixz="-2.24091275712152E-19"
        iyy="0.00679098454718218"
        iyz="3.17277817873348E-18"
        izz="0.0118184008419413" />
    </inertial>
    <visual>
      <origin
        xyz="0 0 0"
        rpy="0 0 0" />
      <geometry>
        <mesh
          filename="package://car/meshes/right_rear_wheel.dae" />
      </geometry>
      <material
        name="">
        <color
          rgba="0.792156862745098 0.819607843137255 0.933333333333333 1" />
      </material>
    </visual>
    <collision>
      <origin
        xyz="0 0 0"
        rpy="0 0 0" />
      <geometry>
        <mesh
          filename="package://car/meshes/right_rear_wheel.dae" />
      </geometry>
    </collision>
  </link>
  <joint
    name="right_rear_wheel_joint"
    type="continuous">
    <origin
      xyz="-0.44015 0.035982 -0.33569"
      rpy="3.1416 -1.5708 0" />
    <parent
      link="base_link" />
    <child
      link="right_rear_wheel" />
    <axis
      xyz="0 0 1" />
    <mimic
      joint="left_rear_wheel_joint"
      multiplier="1"
      offset="0" />
  </joint>
  <link
    name="left_axel">
    <inertial>
      <origin
        xyz="-0.0215345041887456 -2.20129207140207E-07 0.060619132686433"
        rpy="0 0 0" />
      <mass
        value="0.343309331013788" />
      <inertia
        ixx="0.000302393438921681"
        ixy="1.47357459795864E-09"
        ixz="0.000116959796850632"
        iyy="0.000593149233132481"
        iyz="-1.63700675940791E-09"
        izz="0.000404179391395247" />
    </inertial>
    <visual>
      <origin
        xyz="0 0 0"
        rpy="0 0 0" />
      <geometry>
        <mesh
          filename="package://car/meshes/left_axel.dae" />
      </geometry>
      <material
        name="">
        <color
          rgba="0.627450980392157 0.627450980392157 0.627450980392157 1" />
      </material>
    </visual>
    <collision>
      <origin
        xyz="0 0 0"
        rpy="0 0 0" />
      <geometry>
        <mesh
          filename="package://car/meshes/left_axel.dae" />
      </geometry>
    </collision>
  </link>
  <joint
    name="left_axel_joint"
    type="continuous">
    <origin
      xyz="-0.17345 -0.47202 -0.25925"
      rpy="3.1416 0 3.085" />
    <parent
      link="base_link" />
    <child
      link="left_axel" />
    <axis
      xyz="0 0 1" />
  </joint>
  <link
    name="left_front_wheel">
    <inertial>
      <origin
        xyz="5.55111512312578E-17 0 0.0459613313401529"
        rpy="0 0 0" />
      <mass
        value="2.20373338840703" />
      <inertia
        ixx="0.00679098454718218"
        ixy="2.71050543121376E-20"
        ixz="1.81688567186047E-18"
        iyy="0.00679098454718217"
        iyz="1.43656787854329E-18"
        izz="0.0118184008419413" />
    </inertial>
    <visual>
      <origin
        xyz="0 0 0"
        rpy="0 0 0" />
      <geometry>
        <mesh
          filename="package://car/meshes/left_front_wheel.dae" />
      </geometry>
      <material
        name="">
        <color
          rgba="0.792156862745098 0.819607843137255 0.933333333333333 1" />
      </material>
    </visual>
    <collision>
      <origin
        xyz="0 0 0"
        rpy="0 0 0" />
      <geometry>
        <mesh
          filename="package://car/meshes/left_front_wheel.dae" />
      </geometry>
    </collision>
  </link>
  <joint
    name="left_front_wheel_joint"
    type="continuous">
    <origin
      xyz="-0.077138 0 0.076439"
      rpy="1.5708 1.5458 -1.5708" />
    <parent
      link="left_axel" />
    <child
      link="left_front_wheel" />
    <axis
      xyz="0 0 1" />
    <mimic
      joint="left_rear_wheel_joint"
      multiplier="1"
      offset="0" />
  </joint>
  <link
    name="right_axel">
    <inertial>
      <origin
        xyz="-0.0215345244083817 -2.11376193104407E-07 0.0606191290142053"
        rpy="0 0 0" />
      <mass
        value="0.343309204058249" />
      <inertia
        ixx="0.000302393251783979"
        ixy="1.20006118564206E-09"
        ixz="0.000116959723773728"
        iyy="0.000593149258029488"
        iyz="-1.69500251247044E-09"
        izz="0.000404179144905995" />
    </inertial>
    <visual>
      <origin
        xyz="0 0 0"
        rpy="0 0 0" />
      <geometry>
        <mesh
          filename="package://car/meshes/right_axel.dae" />
      </geometry>
      <material
        name="">
        <color
          rgba="0.627450980392157 0.627450980392157 0.627450980392157 1" />
      </material>
    </visual>
    <collision>
      <origin
        xyz="0 0 0"
        rpy="0 0 0" />
      <geometry>
        <mesh
          filename="package://car/meshes/right_axel.dae" />
      </geometry>
    </collision>
  </link>
  <joint
    name="right_axel_joint"
    type="continuous">
    <origin
      xyz="-0.35125 -0.47202 -0.25925"
      rpy="3.1416 0 0" />
    <parent
      link="base_link" />
    <child
      link="right_axel" />
    <axis
      xyz="0 0 1" />
  </joint>
  <link
    name="right_front_wheel">
    <inertial>
      <origin
        xyz="-1.77080572427712E-14 3.66373598126302E-14 -0.0341988929643269"
        rpy="0 0 0" />
      <mass
        value="2.20373338840704" />
      <inertia
        ixx="0.00679098454718218"
        ixy="-7.98286785609436E-33"
        ixz="2.35845205968337E-19"
        iyy="0.00679098454718218"
        iyz="-5.26738303411415E-17"
        izz="0.0118184008419413" />
    </inertial>
    <visual>
      <origin
        xyz="0 0 0"
        rpy="0 0 0" />
      <geometry>
        <mesh
          filename="package://car/meshes/right_front_wheel.dae" />
      </geometry>
      <material
        name="">
        <color
          rgba="0.792156862745098 0.819607843137255 0.933333333333333 1" />
      </material>
    </visual>
    <collision>
      <origin
        xyz="0 0 0"
        rpy="0 0 0" />
      <geometry>
        <mesh
          filename="package://car/meshes/right_front_wheel.dae" />
      </geometry>
    </collision>
  </link>
  <joint
    name="right_front_wheel_joint"
    type="continuous">
    <origin
      xyz="-0.0889 0 0.076439"
      rpy="1.5708 0 1.5708" />
    <parent
      link="right_axel" />
    <child
      link="right_front_wheel" />
    <axis
      xyz="0 0 1" />
    <mimic
      joint="left_front_wheel_joint"
      multiplier="1"
      offset="0" />
  </joint>
   <ros2_control name="GazeboSystem" type="system">
    <hardware>
        <plugin>gazebo_ros2_control/GazeboSystem</plugin>
    </hardware>
 # Velocity Controllers

 <joint name="left_rear_wheel_joint">
     <command_interface name="velocity">
         <param name="min">-1000.0</param>
         <param name="max">1000.0</param>
     </command_interface>
     <state_interface name="position"/>
     <state_interface name="velocity"/>
 </joint>
<joint name="right_rear_wheel_joint">
    <command_interface name="velocity">
        <param name="min">-1000.0</param>
        <param name="max">1000.0</param>
    </command_interface>
    <state_interface name="position"/>
    <state_interface name="velocity"/>
</joint>
 <joint name="left_front_wheel_joint">
     <command_interface name="velocity">
         <param name="min">-1000.0</param>
         <param name="max">1000.0</param>
     </command_interface>
     <state_interface name="position"/>
     <state_interface name="velocity"/>
 </joint>
<joint name="right_front_wheel_joint">
    <command_interface name="velocity">
        <param name="min">-1000.0</param>
        <param name="max">1000.0</param>
    </command_interface>
    <state_interface name="position"/>
    <state_interface name="velocity"/>
</joint>


# Position Controller
 <joint name="left_axel_joint">
     <command_interface name="position">
         <param name="min">-3.14</param>
         <param name="max">3.14</param>
     </command_interface>
     <state_interface name="position"/>
     <state_interface name="velocity"/>
 </joint>
 <joint name="right_axel_joint">
     <command_interface name="position">
         <param name="min">-3.14</param>
         <param name="max">3.14</param>
     </command_interface>
     <state_interface name="position"/>
     <state_interface name="velocity"/>
 </joint>
 </ros2_control>

 <gazebo>
    <plugin filename="libgazebo_ros2_control.so" name="gazebo_ros2_control">
        <parameters>$(find car)/config/control.yaml</parameters>
    </plugin>
 </gazebo>

</robot>