<?xml version="1.0" encoding="utf-8"?>
<!-- This URDF was automatically created by SolidWorks to URDF Exporter! Originally created by Stephen Brawner (brawner@gmail.com) 
     Commit Version: 1.6.0-4-g7f85cfe  Build Version: 1.6.7995.38578
     For more information, please see http://wiki.ros.org/sw_urdf_exporter -->
<robot
  name="Assem2.SLDASM">
  <link
    name="base_link">
    <inertial>
      <origin
        xyz="-0.0128918984763142 0.450966425452628 -0.431554811940461"
        rpy="0 0 0" />
      <mass
        value="130.703409436851" />
      <inertia
        ixx="9.48205837021825"
        ixy="0.000348574852501923"
        ixz="-0.0017160642521088"
        iyy="10.1981840585977"
        iyz="1.39608354050037"
        izz="4.24086791526909" />
    </inertial>
    <visual>
      <origin
        xyz="0 0 0"
        rpy="0 0 0" />
      <geometry>
        <mesh
          filename="package://Assem2.SLDASM/meshes/base_link.STL" />
      </geometry>
      <material
        name="">
        <color
          rgba="0.792156862745098 0.819607843137255 0.933333333333333 1" />
      </material>
    </visual>
    <collision>
      <origin
        xyz="0 0 0"
        rpy="0 0 0" />
      <geometry>
        <mesh
          filename="package://Assem2.SLDASM/meshes/base_link.STL" />
      </geometry>
    </collision>
  </link>
  <link
    name="lidar">
    <inertial>
      <origin
        xyz="-1.66533453693773E-16 1.11022302462516E-16 0.038105927654612"
        rpy="0 0 0" />
      <mass
        value="2.47069918222367" />
      <inertia
        ixx="0.0075722200531262"
        ixy="4.33680868994202E-19"
        ixz="1.4177815111934E-17"
        iyy="0.0075722200531262"
        iyz="-2.48131006824263E-17"
        izz="0.0127540906436804" />
    </inertial>
    <visual>
      <origin
        xyz="0 0 0"
        rpy="0 0 0" />
      <geometry>
        <mesh
          filename="package://Assem2.SLDASM/meshes/lidar.STL" />
      </geometry>
      <material
        name="">
        <color
          rgba="0.0980392156862745 0.0980392156862745 0.0980392156862745 1" />
      </material>
    </visual>
    <collision>
      <origin
        xyz="0 0 0"
        rpy="0 0 0" />
      <geometry>
        <mesh
          filename="package://Assem2.SLDASM/meshes/lidar.STL" />
      </geometry>
    </collision>
  </link>
  <joint
    name="lidar_joint"
    type="continuous">
    <origin
      xyz="-0.0129150284475342 0.554812272899422 0.684495587993352"
      rpy="0 0 2.21735572721632" />
    <parent
      link="base_link" />
    <child
      link="lidar" />
    <axis
      xyz="0 0 1" />
  </joint>
  <link
    name="right_rear_wheel">
    <inertial>
      <origin
        xyz="-1.11022302462516E-16 3.33066907387547E-16 0.0341988929643311"
        rpy="0 0 0" />
      <mass
        value="2.20373338840703" />
      <inertia
        ixx="0.00679098454718218"
        ixy="1.51788304147971E-18"
        ixz="-1.9305156683868E-18"
        iyy="0.00679098454718217"
        iyz="3.39493081395951E-18"
        izz="0.0118184008419413" />
    </inertial>
    <visual>
      <origin
        xyz="0 0 0"
        rpy="0 0 0" />
      <geometry>
        <mesh
          filename="package://Assem2.SLDASM/meshes/right_rear_wheel.STL" />
      </geometry>
      <material
        name="">
        <color
          rgba="0.792156862745098 0.819607843137255 0.933333333333333 1" />
      </material>
    </visual>
    <collision>
      <origin
        xyz="0 0 0"
        rpy="0 0 0" />
      <geometry>
        <mesh
          filename="package://Assem2.SLDASM/meshes/right_rear_wheel.STL" />
      </geometry>
    </collision>
  </link>
  <joint
    name="right_rear_wheel_joint"
    type="revolute">
    <origin
      xyz="-0.19072 0.57197 0.22706"
      rpy="1.5708 -0.93413 -1.5708" />
    <parent
      link="base_link" />
    <child
      link="right_rear_wheel" />
    <axis
      xyz="0 0 1" />
    <limit
      lower="0"
      upper="0"
      effort="0"
      velocity="0" />
    <mimic
      joint="left_rear_wheel_joint"
      multiplier="1"
      offset="0" />
  </joint>
  <link
    name="left_rear_wheel">
    <inertial>
      <origin
        xyz="-4.44089209850063E-16 -8.32667268468867E-17 0.034198892964329"
        rpy="0 0 0" />
      <mass
        value="2.20373338840704" />
      <inertia
        ixx="0.00679098454718218"
        ixy="-2.71050543121376E-20"
        ixz="-4.15014721197344E-18"
        iyy="0.00679098454718218"
        iyz="5.12280309725432E-18"
        izz="0.0118184008419413" />
    </inertial>
    <visual>
      <origin
        xyz="0 0 0"
        rpy="0 0 0" />
      <geometry>
        <mesh
          filename="package://Assem2.SLDASM/meshes/left_rear_wheel.STL" />
      </geometry>
      <material
        name="">
        <color
          rgba="0.792156862745098 0.819607843137255 0.933333333333333 1" />
      </material>
    </visual>
    <collision>
      <origin
        xyz="0 0 0"
        rpy="0 0 0" />
      <geometry>
        <mesh
          filename="package://Assem2.SLDASM/meshes/left_rear_wheel.STL" />
      </geometry>
    </collision>
  </link>
  <joint
    name="left_rear_wheel_joint"
    type="revolute">
    <origin
      xyz="0.16488 0.57197 0.22706"
      rpy="1.5708 -0.034289 1.5708" />
    <parent
      link="base_link" />
    <child
      link="left_rear_wheel" />
    <axis
      xyz="0 0 1" />
    <limit
      lower="0"
      upper="0"
      effort="0"
      velocity="0" />
  </joint>
  <link
    name="right_axel">
    <inertial>
      <origin
        xyz="-0.0215345255884777 -2.05502593310369E-07 -0.0412194584316649"
        rpy="0 0 0" />
      <mass
        value="0.343309256864881" />
      <inertia
        ixx="0.000302393340893422"
        ixy="1.18619617171983E-09"
        ixz="0.000116959746613945"
        iyy="0.000593149262079214"
        iyz="-1.78198026433145E-09"
        izz="0.000404179196007141" />
    </inertial>
    <visual>
      <origin
        xyz="0 0 0"
        rpy="0 0 0" />
      <geometry>
        <mesh
          filename="package://Assem2.SLDASM/meshes/right_axel.STL" />
      </geometry>
      <material
        name="">
        <color
          rgba="0.627450980392157 0.627450980392157 0.627450980392157 1" />
      </material>
    </visual>
    <collision>
      <origin
        xyz="0 0 0"
        rpy="0 0 0" />
      <geometry>
        <mesh
          filename="package://Assem2.SLDASM/meshes/right_axel.STL" />
      </geometry>
    </collision>
  </link>
  <joint
    name="right_axel_joint"
    type="revolute">
    <origin
      xyz="-0.10182 0.063969 0.20166"
      rpy="-3.1416 0 -0.019264" />
    <parent
      link="base_link" />
    <child
      link="right_axel" />
    <axis
      xyz="0 0 1" />
    <limit
      lower="-0.24254"
      upper="0.28106"
      effort="0"
      velocity="0" />
  </joint>
  <link
    name="right_front_wheel">
    <inertial>
      <origin
        xyz="-3.88578058618805E-16 5.79397640976254E-15 0.0388480457107787"
        rpy="0 0 0" />
      <mass
        value="2.20373338840704" />
      <inertia
        ixx="0.00679098454718218"
        ixy="6.50521303491303E-19"
        ixz="-1.06217931585689E-18"
        iyy="0.00679098454718217"
        iyz="-3.30681662608079E-18"
        izz="0.0118184008419413" />
    </inertial>
    <visual>
      <origin
        xyz="0 0 0"
        rpy="0 0 0" />
      <geometry>
        <mesh
          filename="package://Assem2.SLDASM/meshes/right_front_wheel.STL" />
      </geometry>
      <material
        name="">
        <color
          rgba="0.792156862745098 0.819607843137255 0.933333333333333 1" />
      </material>
    </visual>
    <collision>
      <origin
        xyz="0 0 0"
        rpy="0 0 0" />
      <geometry>
        <mesh
          filename="package://Assem2.SLDASM/meshes/right_front_wheel.STL" />
      </geometry>
    </collision>
  </link>
  <joint
    name="right_front_wheel_joint"
    type="revolute">
    <origin
      xyz="-0.084251 0 -0.0254"
      rpy="1.5708 1.3589 -1.5708" />
    <parent
      link="right_axel" />
    <child
      link="right_front_wheel" />
    <axis
      xyz="0 0 1" />
    <limit
      lower="0"
      upper="0"
      effort="0"
      velocity="0" />
  </joint>
  <link
    name="left_axel">
    <inertial>
      <origin
        xyz="-0.0215345010339004 -2.23897531057005E-07 -0.0412194644195421"
        rpy="0 0 0" />
      <mass
        value="0.343309335035793" />
      <inertia
        ixx="0.000302393392753759"
        ixy="1.48778172553109E-09"
        ixz="0.000116959879485354"
        iyy="0.000593149368150714"
        iyz="-1.66748643075836E-09"
        izz="0.000404179409963257" />
    </inertial>
    <visual>
      <origin
        xyz="0 0 0"
        rpy="0 0 0" />
      <geometry>
        <mesh
          filename="package://Assem2.SLDASM/meshes/left_axel.STL" />
      </geometry>
      <material
        name="">
        <color
          rgba="0.627450980392157 0.627450980392157 0.627450980392157 1" />
      </material>
    </visual>
    <collision>
      <origin
        xyz="0 0 0"
        rpy="0 0 0" />
      <geometry>
        <mesh
          filename="package://Assem2.SLDASM/meshes/left_axel.STL" />
      </geometry>
    </collision>
  </link>
  <joint
    name="left_axel_joint"
    type="revolute">
    <origin
      xyz="0.075985 0.063969 0.20166"
      rpy="3.1416 0 3.1382" />
    <parent
      link="base_link" />
    <child
      link="left_axel" />
    <axis
      xyz="0 0 1" />
    <limit
      lower="-0.25839"
      upper="0.2652"
      effort="0"
      velocity="0" />
  </joint>
  <link
    name="left_front_wheel">
    <inertial>
      <origin
        xyz="-7.49400541621981E-16 4.44089209850063E-16 0.0351221259560628"
        rpy="0 0 0" />
      <mass
        value="2.20373338840703" />
      <inertia
        ixx="0.00679098454718218"
        ixy="0"
        ixz="-1.92276479026726E-18"
        iyy="0.00679098454718217"
        iyz="-5.78862316153589E-18"
        izz="0.0118184008419413" />
    </inertial>
    <visual>
      <origin
        xyz="0 0 0"
        rpy="0 0 0" />
      <geometry>
        <mesh
          filename="package://Assem2.SLDASM/meshes/left_front_wheel.STL" />
      </geometry>
      <material
        name="">
        <color
          rgba="0.792156862745098 0.819607843137255 0.933333333333333 1" />
      </material>
    </visual>
    <collision>
      <origin
        xyz="0 0 0"
        rpy="0 0 0" />
      <geometry>
        <mesh
          filename="package://Assem2.SLDASM/meshes/left_front_wheel.STL" />
      </geometry>
    </collision>
  </link>
  <joint
    name="left_front_wheel_joint"
    type="revolute">
    <origin
      xyz="-0.087977 0 -0.0254"
      rpy="1.5708 1.1228 -1.5708" />
    <parent
      link="left_axel" />
    <child
      link="left_front_wheel" />
    <axis
      xyz="0 0 1" />
    <limit
      lower="0"
      upper="0"
      effort="0"
      velocity="0" />
  </joint>
</robot>